2023-09-01 20:59:48,962 INFO    StreamThr :46830 [internal.py:wandb_internal():86] W&B internal server running at pid: 46830, started at: 2023-09-01 20:59:48.962177
2023-09-01 20:59:48,964 DEBUG   HandlerThread:46830 [handler.py:handle_request():144] handle_request: status
2023-09-01 20:59:48,976 INFO    WriterThread:46830 [datastore.py:open_for_write():85] open: /Users/fatmaoztel/Desktop/Fatima Projects/CTR-prediction/CTR-prediction/wandb/run-20230901_205948-3vgtk49n/run-3vgtk49n.wandb
2023-09-01 20:59:48,977 DEBUG   SenderThread:46830 [sender.py:send():379] send: header
2023-09-01 20:59:48,995 DEBUG   SenderThread:46830 [sender.py:send():379] send: run
2023-09-01 20:59:54,018 DEBUG   HandlerThread:46830 [handler.py:handle_request():144] handle_request: keepalive
2023-09-01 20:59:59,035 DEBUG   HandlerThread:46830 [handler.py:handle_request():144] handle_request: keepalive
2023-09-01 21:00:04,055 DEBUG   HandlerThread:46830 [handler.py:handle_request():144] handle_request: keepalive
2023-09-01 21:00:09,078 DEBUG   HandlerThread:46830 [handler.py:handle_request():144] handle_request: keepalive
2023-09-01 21:00:14,103 DEBUG   HandlerThread:46830 [handler.py:handle_request():144] handle_request: keepalive
2023-09-01 21:00:19,121 DEBUG   HandlerThread:46830 [handler.py:handle_request():144] handle_request: keepalive
2023-09-01 21:00:24,145 DEBUG   HandlerThread:46830 [handler.py:handle_request():144] handle_request: keepalive
2023-09-01 21:00:27,282 INFO    SenderThread:46830 [retry.py:__call__():172] Retry attempt failed:
Traceback (most recent call last):
  File "/opt/homebrew/lib/python3.11/site-packages/urllib3/connectionpool.py", line 449, in _make_request
    six.raise_from(e, None)
  File "<string>", line 3, in raise_from
  File "/opt/homebrew/lib/python3.11/site-packages/urllib3/connectionpool.py", line 444, in _make_request
    httplib_response = conn.getresponse()
                       ^^^^^^^^^^^^^^^^^^
  File "/opt/homebrew/Cellar/python@3.11/3.11.2_1/Frameworks/Python.framework/Versions/3.11/lib/python3.11/http/client.py", line 1374, in getresponse
    response.begin()
  File "/opt/homebrew/Cellar/python@3.11/3.11.2_1/Frameworks/Python.framework/Versions/3.11/lib/python3.11/http/client.py", line 318, in begin
    version, status, reason = self._read_status()
                              ^^^^^^^^^^^^^^^^^^^
  File "/opt/homebrew/Cellar/python@3.11/3.11.2_1/Frameworks/Python.framework/Versions/3.11/lib/python3.11/http/client.py", line 279, in _read_status
    line = str(self.fp.readline(_MAXLINE + 1), "iso-8859-1")
               ^^^^^^^^^^^^^^^^^^^^^^^^^^^^^^
  File "/opt/homebrew/Cellar/python@3.11/3.11.2_1/Frameworks/Python.framework/Versions/3.11/lib/python3.11/socket.py", line 706, in readinto
    return self._sock.recv_into(b)
           ^^^^^^^^^^^^^^^^^^^^^^^
  File "/opt/homebrew/Cellar/python@3.11/3.11.2_1/Frameworks/Python.framework/Versions/3.11/lib/python3.11/ssl.py", line 1278, in recv_into
    return self.read(nbytes, buffer)
           ^^^^^^^^^^^^^^^^^^^^^^^^^
  File "/opt/homebrew/Cellar/python@3.11/3.11.2_1/Frameworks/Python.framework/Versions/3.11/lib/python3.11/ssl.py", line 1134, in read
    return self._sslobj.read(len, buffer)
           ^^^^^^^^^^^^^^^^^^^^^^^^^^^^^^
TimeoutError: The read operation timed out

During handling of the above exception, another exception occurred:

Traceback (most recent call last):
  File "/opt/homebrew/lib/python3.11/site-packages/requests/adapters.py", line 489, in send
    resp = conn.urlopen(
           ^^^^^^^^^^^^^
  File "/opt/homebrew/lib/python3.11/site-packages/urllib3/connectionpool.py", line 787, in urlopen
    retries = retries.increment(
              ^^^^^^^^^^^^^^^^^^
  File "/opt/homebrew/lib/python3.11/site-packages/urllib3/util/retry.py", line 550, in increment
    raise six.reraise(type(error), error, _stacktrace)
          ^^^^^^^^^^^^^^^^^^^^^^^^^^^^^^^^^^^^^^^^^^^^
  File "/opt/homebrew/lib/python3.11/site-packages/urllib3/packages/six.py", line 770, in reraise
    raise value
  File "/opt/homebrew/lib/python3.11/site-packages/urllib3/connectionpool.py", line 703, in urlopen
    httplib_response = self._make_request(
                       ^^^^^^^^^^^^^^^^^^^
  File "/opt/homebrew/lib/python3.11/site-packages/urllib3/connectionpool.py", line 451, in _make_request
    self._raise_timeout(err=e, url=url, timeout_value=read_timeout)
  File "/opt/homebrew/lib/python3.11/site-packages/urllib3/connectionpool.py", line 340, in _raise_timeout
    raise ReadTimeoutError(
urllib3.exceptions.ReadTimeoutError: HTTPSConnectionPool(host='api.wandb.ai', port=443): Read timed out. (read timeout=10)

During handling of the above exception, another exception occurred:

Traceback (most recent call last):
  File "/opt/homebrew/lib/python3.11/site-packages/wandb/sdk/lib/retry.py", line 131, in __call__
    result = self._call_fn(*args, **kwargs)
             ^^^^^^^^^^^^^^^^^^^^^^^^^^^^^^
  File "/opt/homebrew/lib/python3.11/site-packages/wandb/sdk/internal/internal_api.py", line 323, in execute
    return self.client.execute(*args, **kwargs)  # type: ignore
           ^^^^^^^^^^^^^^^^^^^^^^^^^^^^^^^^^^^^
  File "/opt/homebrew/lib/python3.11/site-packages/wandb/vendor/gql-0.2.0/wandb_gql/client.py", line 52, in execute
    result = self._get_result(document, *args, **kwargs)
             ^^^^^^^^^^^^^^^^^^^^^^^^^^^^^^^^^^^^^^^^^^^
  File "/opt/homebrew/lib/python3.11/site-packages/wandb/vendor/gql-0.2.0/wandb_gql/client.py", line 60, in _get_result
    return self.transport.execute(document, *args, **kwargs)
           ^^^^^^^^^^^^^^^^^^^^^^^^^^^^^^^^^^^^^^^^^^^^^^^^^
  File "/opt/homebrew/lib/python3.11/site-packages/wandb/sdk/lib/gql_request.py", line 55, in execute
    request = self.session.post(self.url, **post_args)
              ^^^^^^^^^^^^^^^^^^^^^^^^^^^^^^^^^^^^^^^^
  File "/opt/homebrew/lib/python3.11/site-packages/requests/sessions.py", line 635, in post
    return self.request("POST", url, data=data, json=json, **kwargs)
           ^^^^^^^^^^^^^^^^^^^^^^^^^^^^^^^^^^^^^^^^^^^^^^^^^^^^^^^^^
  File "/opt/homebrew/lib/python3.11/site-packages/requests/sessions.py", line 587, in request
    resp = self.send(prep, **send_kwargs)
           ^^^^^^^^^^^^^^^^^^^^^^^^^^^^^^
  File "/opt/homebrew/lib/python3.11/site-packages/requests/sessions.py", line 701, in send
    r = adapter.send(request, **kwargs)
        ^^^^^^^^^^^^^^^^^^^^^^^^^^^^^^^
  File "/opt/homebrew/lib/python3.11/site-packages/requests/adapters.py", line 578, in send
    raise ReadTimeout(e, request=request)
requests.exceptions.ReadTimeout: HTTPSConnectionPool(host='api.wandb.ai', port=443): Read timed out. (read timeout=10)
2023-09-01 21:00:29,163 DEBUG   HandlerThread:46830 [handler.py:handle_request():144] handle_request: keepalive
2023-09-01 21:00:34,185 DEBUG   HandlerThread:46830 [handler.py:handle_request():144] handle_request: keepalive
2023-09-01 21:00:39,206 DEBUG   HandlerThread:46830 [handler.py:handle_request():144] handle_request: keepalive
2023-09-01 21:00:44,228 DEBUG   HandlerThread:46830 [handler.py:handle_request():144] handle_request: keepalive
2023-09-01 21:00:49,247 DEBUG   HandlerThread:46830 [handler.py:handle_request():144] handle_request: cancel
2023-09-01 21:00:49,247 DEBUG   HandlerThread:46830 [handler.py:handle_request():144] handle_request: cancel
2023-09-01 21:00:49,248 DEBUG   SenderThread:46830 [sender.py:send():388] Record cancelled: run
2023-09-01 21:00:49,248 DEBUG   HandlerThread:46830 [handler.py:handle_request():144] handle_request: status_report
2023-09-01 21:00:54,262 DEBUG   HandlerThread:46830 [handler.py:handle_request():144] handle_request: status_report
2023-09-01 21:00:59,278 DEBUG   HandlerThread:46830 [handler.py:handle_request():144] handle_request: status_report
2023-09-01 21:01:04,295 DEBUG   HandlerThread:46830 [handler.py:handle_request():144] handle_request: status_report
2023-09-01 21:01:09,311 DEBUG   HandlerThread:46830 [handler.py:handle_request():144] handle_request: status_report
2023-09-01 21:01:14,332 DEBUG   HandlerThread:46830 [handler.py:handle_request():144] handle_request: status_report
2023-09-01 21:01:19,351 DEBUG   HandlerThread:46830 [handler.py:handle_request():144] handle_request: status_report
2023-09-01 21:01:24,373 DEBUG   HandlerThread:46830 [handler.py:handle_request():144] handle_request: status_report
2023-09-01 21:01:29,390 DEBUG   HandlerThread:46830 [handler.py:handle_request():144] handle_request: status_report
2023-09-01 21:01:34,405 DEBUG   HandlerThread:46830 [handler.py:handle_request():144] handle_request: status_report
2023-09-01 21:01:39,403 DEBUG   HandlerThread:46830 [handler.py:handle_request():144] handle_request: shutdown
2023-09-01 21:01:39,404 INFO    HandlerThread:46830 [handler.py:finish():861] shutting down handler
2023-09-01 21:01:39,418 INFO    SenderThread:46830 [sender.py:finish():1552] shutting down sender
2023-09-01 21:01:39,430 INFO    WriterThread:46830 [datastore.py:close():294] close: /Users/fatmaoztel/Desktop/Fatima Projects/CTR-prediction/CTR-prediction/wandb/run-20230901_205948-3vgtk49n/run-3vgtk49n.wandb
